import {
  setupFastifyTestEnvironment,
  teardownFastifyTestEnvironment,
} from "@lasl/test-utils-fastify/setup-utils";
import type { FastifyReply } from "fastify";
import { StatusCodes } from "http-status-codes";
import mongoose, { Error as MongooseError } from "mongoose";
import {
  afterAll,
  beforeAll,
  beforeEach,
  describe,
  expect,
  it,
  vi,
} from "vitest";
import { buildApp } from "@/src/app.ts";
import { createUserHandler } from "@/src/controller/create.user.controller.ts";
import { createUser } from "@/src/service/user.service.ts";
import { mockUserData, mockUserInputData } from "../__mocks__/user.mock.ts";

vi.mock("@/src/service/user.service", () => ({
  createUser: vi.fn(),
}));

// biome-ignore lint/complexity/noExcessiveLinesPerFunction: ok here
describe("User service", () => {
  const mockReply = (): FastifyReply => {
    const reply = {
      status: vi.fn(),
      send: vi.fn(),
    };
    reply.status = vi.fn().mockReturnValue(reply);
    reply.send = vi.fn().mockReturnValue(reply);
    return reply as unknown as FastifyReply;
  };

  const req = {
    body: mockUserData,
    server: {
      sendMail: vi.fn(),
    },
    headers: {},
    log: { error: vi.fn() },
  };

  beforeAll(async () => {
    await setupFastifyTestEnvironment({ buildApp, useMongo: true });
  });

  afterAll(async () => {
    await teardownFastifyTestEnvironment();
  });

  beforeEach(async () => {
    await mongoose.connection.db?.dropDatabase();
    vi.clearAllMocks();
  });

  it("should create a user and return 200", async () => {
    (createUser as ReturnType<typeof vi.fn>).mockResolvedValueOnce({
      firstName: mockUserInputData.firstName,
      email: mockUserInputData.email,
      verificationCode: "Test245",
    });

    const reply = mockReply();

    // @ts-expect-error ok in test
    await createUserHandler(req, reply);

    expect(createUser).toHaveBeenCalledWith(mockUserData);
    expect(reply.status).toHaveBeenCalledWith(StatusCodes.OK);
    expect(reply.send).toHaveBeenCalledWith({
      message: "User successfully created",
    });
  });

  it("should return 422 for validation error", async () => {
    const error = new MongooseError.ValidationError();
    error.message = "Validation failed";

    (createUser as ReturnType<typeof vi.fn>).mockRejectedValueOnce(error);
    const reply = mockReply();

    // @ts-expect-error ok in test
    await createUserHandler(req, reply);

    expect(reply.status).toHaveBeenCalledWith(StatusCodes.UNPROCESSABLE_ENTITY);
    expect(reply.send).toHaveBeenCalledWith({
      message: `Could not create user due to validation failure: ${error.message}`,
      errors: error.errors,
    });
  });

  it("should return 409 if user already exists", async () => {
    const duplicateError = new Error("Duplicate key") as Error & {
      code: number;
    };
    // biome-ignore lint/style/noMagicNumbers: acceptable here
    duplicateError.code = 11_000;

    (createUser as ReturnType<typeof vi.fn>).mockRejectedValueOnce(
      duplicateError,
    );

    const reply = mockReply();

    // @ts-expect-error ok in test
    await createUserHandler(req, reply);

    expect(reply.status).toHaveBeenCalledWith(StatusCodes.CONFLICT);
    expect(reply.send).toHaveBeenCalledWith({
      message: "Account already exists",
    });
  });

  it("should return 500 for unknown error", async () => {
    const unknownError = new Error("Something went wrong");

    (createUser as ReturnType<typeof vi.fn>).mockRejectedValueOnce(
      unknownError,
    );

    const reply = mockReply();

    // @ts-expect-error ok in test
    await createUserHandler(req, reply);

    expect(reply.status).toHaveBeenCalledWith(
      StatusCodes.INTERNAL_SERVER_ERROR,
    );
    expect(reply.send).toHaveBeenCalledWith({
      message: `Unexpected error occurred: ${unknownError}`,
    });
  });
});
